Workbook

Sheet Leads
A1: # | B1: Prior. | C1: Score | D1: Tipo | E1: Categoria | F1: Especialidade / nicho | G1: Nome | H1: Instagram | I1: Bairro | J1: Seguidores | K1: Registro | L1: Site atual | M1: Link da bio | N1: Último post | O1: Prévia | P1: Mensagem 1 (DM) | Q1: Follow-up (2 dias) | R1: Status | S1: Data contato | T1: Próximo passo | U1: Observação
A2: 1 | B2: A | C2: 10 | D2: Profissional | E2: Dentista | F2: odontologia | G2: Odonto8 Tatuapé | H2: @odonto8.tatuape | I2: Tatuapé | J2: 7116 | K2: CRO-CL 17739 | L2: nao encontrado | O2: Abrir prévia | P2: Oi, pessoal da Odonto8 Tatuapé! Sou o [SEU NOME], da Downway. Acompanho o conteúdo de vocês de odontologia aqui no Instagram e montei uma prévia de site para a Odonto8 Tatuapé, já com CRO e responsável técnico em destaque: https://downway.com.br/demo/odonto8-tatuape/ Hoje, quem pesquisa "dentista no Tatuapé" no Google encontra outros profissionais. Com o site, essa pessoa chega até vocês e já fala no WhatsApp. Posso mostrar como fica no ar? | Q2: Oi! Conseguiu ver a prévia do site? Se quiser, ajusto cores, fotos ou textos para ficar com a cara do seu trabalho. A prévia fica no ar por 7 dias. | R2: Novo
A3: 2 | B3: A | C3: 9 | D3: Profissional | E3: Advogado | F3: família | G3: Ana Ricarte Advocacia | H3: @anaricarteadvogada | I3: São Paulo | J3: 14000 | L3: nao encontrado | O3: Abrir prévia | P3: Oi, Ana! Sou o [SEU NOME], da Downway. Acompanho seu conteúdo de direito de família aqui no Instagram e montei uma prévia de site para você, já seguindo as regras de publicidade da OAB (Provimento 205/2021): https://downway.com.br/demo/anaricarteadvogada/ Hoje, quem pesquisa "advogado de família em São Paulo" no Google encontra outros profissionais. Com o site, essa pessoa chega até você e já fala no WhatsApp. Posso mostrar como fica no ar? | Q3: Oi! Conseguiu ver a prévia do site? Se quiser, ajusto cores, fotos ou textos para ficar com a cara do seu trabalho. A prévia fica no ar por 7 dias. | R3: Novo
A4: 3 | B4: A | C4: 9 | D4: Profissional | E4: Advogado | F4: família | G4: Andreia Pereira Advocacia | H4: @andreiapereira.adv | I4: São Paulo | J4: 28000 | L4: nao encontrado | O4: Abrir prévia | P4: Oi, Andreia! Sou o [SEU NOME], da Downway. Acompanho seu conteúdo de direito de família aqui no Instagram e montei uma prévia de site para você, já seguindo as regras de publicidade da OAB (Provimento 205/2021): https://downway.com.br/demo/andreiapereira-adv/ Hoje, quem pesquisa "advogado de família em São Paulo" no Google encontra outros profissionais. Com o site, essa pessoa chega até você e já fala no WhatsApp. Posso mostrar como fica no ar? | Q4: Oi! Conseguiu ver a prévia do site? Se quiser, ajusto cores, fotos ou textos para ficar com a cara do seu trabalho. A prévia fica no ar por 7 dias. | R4: Novo
A5: 4 | B5: A | C5: 9 | D5: Profissional | E5: Advogado | F5: família | G5: Barbara Ferreira Advocacia | H5: @baferreiraadv | I5: São Paulo | J5: 7362 | L5: nao encontrado | O5: Abrir prévia | P5: Oi, Barbara! Sou o [SEU NOME], da Downway. Acompanho seu conteúdo de direito de família aqui no Instagram e montei uma prévia de site para você, já seguindo as regras de publicidade da OAB (Provimento 205/2021): https://downway.com.br/demo/baferreiraadv/ Hoje, quem pesquisa "advogado de família em São Paulo" no Google encontra outros profissionais. Com o site, essa pessoa chega até você e já fala no WhatsApp. Posso mostrar como fica no ar? | Q5: Oi! Conseguiu ver a prévia do site? Se quiser, ajusto cores, fotos ou textos para ficar com a cara do seu trabalho. A prévia fica no ar por 7 dias. | R5: Novo
A6: 5 | B6: A | C6: 9 | D6: Profissional | E6: Advogado | F6: consumidor | G6: Caio De Luccas Advocacia | H6: @caiodeluccas.adv | I6: São Paulo | J6: 12000 | L6: nao encontrado | O6: Abrir prévia | P6: Oi, Caio! Sou o [SEU NOME], da Downway. Acompanho seu conteúdo de direito do consumidor aqui no Instagram e montei uma prévia de site para você, já seguindo as regras de publicidade da OAB (Provimento 205/2021): https://downway.com.br/demo/caiodeluccas-adv/ Hoje, quem pesquisa "advogado do consumidor em São Paulo" no Google encontra outros profissionais. Com o site, essa pessoa chega até você e já fala no WhatsApp. Posso mostrar como fica no ar? | Q6: Oi! Conseguiu ver a prévia do site? Se quiser, ajusto cores, fotos ou textos para ficar com a cara do seu trabalho. A prévia fica no ar por 7 dias. | R6: Novo
A7: 6 | B7: A | C7: 9 | D7: Profissional | E7: Advogado | F7: trabalhista | G7: Jonas Figueiredo Advocacia | H7: @jonasfigueiredoadv | I7: São Paulo | J7: 5756 | L7: nao encontrado | O7: Abrir prévia | P7: Oi, Jonas! Sou o [SEU NOME], da Downway. Acompanho seu conteúdo de direito trabalhista aqui no Instagram e montei uma prévia de site para você, já seguindo as regras de publicidade da OAB (Provimento 205/2021): https://downway.com.br/demo/jonasfigueiredoadv/ Hoje, quem pesquisa "advogado trabalhista em São Paulo" no Google encontra outros profissionais. Com o site, essa pessoa chega até você e já fala no WhatsApp. Posso mostrar como fica no ar? | Q7: Oi! Conseguiu ver a prévia do site? Se quiser, ajusto cores, fotos ou textos para ficar com a cara do seu trabalho. A prévia fica no ar por 7 dias. | R7: Novo
A8: 7 | B8: A | C8: 9 | D8: Profissional | E8: Advogado | F8: família | G8: Ligia Bertaggia Advocacia | H8: @direitodefamiliaesucessoes | I8: São Paulo | J8: 13000 | L8: nao encontrado | O8: Abrir prévia | P8: Oi, Ligia! Sou o [SEU NOME], da Downway. Acompanho seu conteúdo de direito de família aqui no Instagram e montei uma prévia de site para você, já seguindo as regras de publicidade da OAB (Provimento 205/2021): https://downway.com.br/demo/direitodefamiliaesucessoes/ Hoje, quem pesquisa "advogado de família em São Paulo" no Google encontra outros profissionais. Com o site, essa pessoa chega até você e já fala no WhatsApp. Posso mostrar como fica no ar? | Q8: Oi! Conseguiu ver a prévia do site? Se quiser, ajusto cores, fotos ou textos para ficar com a cara do seu trabalho. A prévia fica no ar por 7 dias. | R8: Novo
A9: 8 | B9: A | C9: 9 | D9: Profissional | E9: Advogado | F9: família | G9: Mariana Regis Advocacia | H9: @marianaregisadvogada | I9: São Paulo | J9: 34000 | L9: nao encontrado | O9: Abrir prévia | P9: Oi, Mariana! Sou o [SEU NOME], da Downway. Acompanho seu conteúdo de direito de família aqui no Instagram e montei uma prévia de site para você, já seguindo as regras de publicidade da OAB (Provimento 205/2021): https://downway.com.br/demo/marianaregisadvogada/ Hoje, quem pesquisa "advogado de família em São Paulo" no Google encontra outros profissionais. Com o site, essa pessoa chega até você e já fala no WhatsApp. Posso mostrar como fica no ar? | Q9: Oi! Conseguiu ver a prévia do site? Se quiser, ajusto cores, fotos ou textos para ficar com a cara do seu trabalho. A prévia fica no ar por 7 dias. | R9: Novo
A10: 9 | B10: A | C10: 9 | D10: Profissional | E10: Advogado | F10: previdenciário | G10: Suzana de Amorim Advocacia | H10: @suzanadeamorim | I10: São Paulo | J10: 49000 | L10: nao encontrado | O10: Abrir prévia | P10: Oi, Suzana! Sou o [SEU NOME], da Downway. Acompanho seu conteúdo de direito previdenciário aqui no Instagram e montei uma prévia de site para você, já seguindo as regras de publicidade da OAB (Provimento 205/2021): https://downway.com.br/demo/suzanadeamorim/ Hoje, quem pesquisa "advogado previdenciário em São Paulo" no Google encontra outros profissionais. Com o site, essa pessoa chega até você e já fala no WhatsApp. Posso mostrar como fica no ar? | Q10: Oi! Conseguiu ver a prévia do site? Se quiser, ajusto cores, fotos ou textos para ficar com a cara do seu trabalho. A prévia fica no ar por 7 dias. | R10: Novo | U10: Atende Brasil todo = site traz cliente de fora
A11: 10 | B11: A | C11: 9 | D11: Profissional | E11: Advogado | F11: imobiliário | G11: Vanessa Leite Advocacia | H11: @vanessaleite_adv | I11: São Paulo | J11: 4621 | L11: nao encontrado | O11: Abrir prévia | P11: Oi, Vanessa! Sou o [SEU NOME], da Downway. Acompanho seu conteúdo de direito imobiliário aqui no Instagram e montei uma prévia de site para você, já seguindo as regras de publicidade da OAB (Provimento 205/2021): https://downway.com.br/demo/vanessaleite-adv/ Hoje, quem pesquisa "advogado imobiliário em São Paulo" no Google encontra outros profissionais. Com o site, essa pessoa chega até você e já fala no WhatsApp. Posso mostrar como fica no ar? | Q11: Oi! Conseguiu ver a prévia do site? Se quiser, ajusto cores, fotos ou textos para ficar com a cara do seu trabalho. A prévia fica no ar por 7 dias. | R11: Novo
A12: 11 | B12: A | C12: 9 | D12: Profissional | E12: Advogado | F12: consumidor | G12: Victor Tosta Advocacia | H12: @advvictortosta | I12: São Paulo | J12: 6244 | L12: nao encontrado | O12: Abrir prévia | P12: Oi, Victor! Sou o [SEU NOME], da Downway. Acompanho seu conteúdo de direito do consumidor aqui no Instagram e montei uma prévia de site para você, já seguindo as regras de publicidade da OAB (Provimento 205/2021): https://downway.com.br/demo/advvictortosta/ Hoje, quem pesquisa "advogado do consumidor em São Paulo" no Google encontra outros profissionais. Com o site, essa pessoa chega até você e já fala no WhatsApp. Posso mostrar como fica no ar? | Q12: Oi! Conseguiu ver a prévia do site? Se quiser, ajusto cores, fotos ou textos para ficar com a cara do seu trabalho. A prévia fica no ar por 7 dias. | R12: Novo
A13: 12 | B13: A | C13: 9 | D13: Profissional | E13: Dentista | F13: odontologia | G13: Prez Odonto Tatuapé | H13: @prezodonto | I13: Tatuapé | J13: 10000 | L13: nao encontrado | O13: Abrir prévia | P13: Oi, pessoal da Prez Odonto Tatuapé! Sou o [SEU NOME], da Downway. Acompanho o conteúdo de vocês de odontologia aqui no Instagram e montei uma prévia de site para a Prez Odonto Tatuapé, já com CRO e responsável técnico em destaque: https://downway.com.br/demo/prezodonto/ Hoje, quem pesquisa "dentista no Tatuapé" no Google encontra outros profissionais. Com o site, essa pessoa chega até vocês e já fala no WhatsApp. Posso mostrar como fica no ar? | Q13: Oi! Conseguiu ver a prévia do site? Se quiser, ajusto cores, fotos ou textos para ficar com a cara do seu trabalho. A prévia fica no ar por 7 dias. | R13: Novo
A14: 13 | B14: A | C14: 9 | D14: Profissional | E14: Médico | F14: cardiologia | G14: Dr. Lucas Trindade | H14: @drlucastrindade | I14: Itaim Bibi | K14: CRM-SP 168.448 | L14: nao encontrado | O14: Abrir prévia | P14: Oi, Dr. Lucas! Sou o [SEU NOME], da Downway. Acompanho seu conteúdo de cardiologia aqui no Instagram e montei uma prévia de site para você, já seguindo a resolução de publicidade médica do CFM (2.336/2023): https://downway.com.br/demo/drlucastrindade/ Hoje, quem pesquisa "cardiologista no Itaim" no Google encontra outros profissionais. Com o site, essa pessoa chega até você e já fala no WhatsApp. Posso mostrar como fica no ar? | Q14: Oi! Conseguiu ver a prévia do site? Se quiser, ajusto cores, fotos ou textos para ficar com a cara do seu trabalho. A prévia fica no ar por 7 dias. | R14: Novo
A15: 14 | B15: A | C15: 9 | D15: Profissional | E15: Médico | F15: dermatologia | G15: Dra. Carmem Durazzo | H15: @carmemdermatologista | I15: São Paulo | K15: CRM 59801 · RQE 45813 | L15: nao encontrado | O15: Abrir prévia | P15: Oi, Dra. Carmem! Sou o [SEU NOME], da Downway. Acompanho seu conteúdo de dermatologia aqui no Instagram e montei uma prévia de site para você, já seguindo a resolução de publicidade médica do CFM (2.336/2023): https://downway.com.br/demo/carmemdermatologista/ Hoje, quem pesquisa "dermatologista em São Paulo" no Google encontra outros profissionais. Com o site, essa pessoa chega até você e já fala no WhatsApp. Posso mostrar como fica no ar? | Q15: Oi! Conseguiu ver a prévia do site? Se quiser, ajusto cores, fotos ou textos para ficar com a cara do seu trabalho. A prévia fica no ar por 7 dias. | R15: Novo
A16: 15 | B16: A | C16: 9 | D16: Profissional | E16: Médico | F16: endocrinologia | G16: Dra. Paula Pires Giacomini | H16: @drapaulapires | I16: São Paulo | K16: CRM 138809 · RQE 47818 | L16: nao encontrado | O16: Abrir prévia | P16: Oi, Dra. Paula! Sou o [SEU NOME], da Downway. Acompanho seu conteúdo de endocrinologia aqui no Instagram e montei uma prévia de site para você, já seguindo a resolução de publicidade médica do CFM (2.336/2023): https://downway.com.br/demo/drapaulapires/ Hoje, quem pesquisa "endocrinologista em São Paulo" no Google encontra outros profissionais. Com o site, essa pessoa chega até você e já fala no WhatsApp. Posso mostrar como fica no ar? | Q16: Oi! Conseguiu ver a prévia do site? Se quiser, ajusto cores, fotos ou textos para ficar com a cara do seu trabalho. A prévia fica no ar por 7 dias. | R16: Novo
A17: 16 | B17: A | C17: 9 | D17: Profissional | E17: Nutricionista | F17: nutrição infantil | G17: Paula Stancari Nutrição Materno-Infantil | H17: @nutripaulastancari | I17: Vila Mariana | L17: nao encontrado | O17: Abrir prévia | P17: Oi, Paula! Sou o [SEU NOME], da Downway. Acompanho seu conteúdo de nutrição materno-infantil aqui no Instagram e montei uma prévia de site para você, já com o CRN em destaque e dentro das regras do conselho: https://downway.com.br/demo/nutripaulastancari/ Hoje, quem pesquisa "nutricionista infantil em São Paulo" no Google encontra outros profissionais. Com o site, essa pessoa chega até você e já fala no WhatsApp. Posso mostrar como fica no ar? | Q17: Oi! Conseguiu ver a prévia do site? Se quiser, ajusto cores, fotos ou textos para ficar com a cara do seu trabalho. A prévia fica no ar por 7 dias. | R17: Novo | U17: Endereço: R. Cubatão, 929
A18: 17 | B18: A | C18: 9 | D18: Profissional | E18: Nutricionista | F18: nutrição | G18: Tainá Carvalho Nutricionista | H18: @nutricionistaesportivo_taina | I18: São Paulo | K18: CRN 34890 | L18: nao encontrado | O18: Abrir prévia | P18: Oi, Tainá! Sou o [SEU NOME], da Downway. Acompanho seu conteúdo de nutrição aqui no Instagram e montei uma prévia de site para você, já com o CRN em destaque e dentro das regras do conselho: https://downway.com.br/demo/nutricionistaesportivo-taina/ Hoje, quem pesquisa "nutricionista em São Paulo" no Google encontra outros profissionais. Com o site, essa pessoa chega até você e já fala no WhatsApp. Posso mostrar como fica no ar? | Q18: Oi! Conseguiu ver a prévia do site? Se quiser, ajusto cores, fotos ou textos para ficar com a cara do seu trabalho. A prévia fica no ar por 7 dias. | R18: Novo
A19: 18 | B19: A | C19: 9 | D19: Profissional | E19: Psicólogo | F19: psicologia | G19: Beatriz Sampaio Arraes Psicóloga | H19: @psicologadeplantao | I19: São Paulo | K19: CRP 06/145121 | L19: nao encontrado | O19: Abrir prévia | P19: Oi, Beatriz! Sou o [SEU NOME], da Downway. Acompanho seu conteúdo de psicologia aqui no Instagram e montei uma prévia de site para você, já dentro do código de ética do CFP: https://downway.com.br/demo/psicologadeplantao/ Hoje, quem pesquisa "psicóloga em São Paulo" no Google encontra outros profissionais. Com o site, essa pessoa chega até você e já fala no WhatsApp. Posso mostrar como fica no ar? | Q19: Oi! Conseguiu ver a prévia do site? Se quiser, ajusto cores, fotos ou textos para ficar com a cara do seu trabalho. A prévia fica no ar por 7 dias. | R19: Novo
A20: 19 | B20: A | C20: 9 | D20: Profissional | E20: Psicólogo | F20: psicologia | G20: Clínica Internaliza Psicologia | H20: @internalizapsicologia | I20: São Paulo | K20: CRP 06/11127/J | L20: nao encontrado | O20: Abrir prévia | P20: Oi, pessoal da Clínica Internaliza Psicologia! Sou o [SEU NOME], da Downway. Acompanho o conteúdo de vocês de psicologia aqui no Instagram e montei uma prévia de site para a Clínica Internaliza Psicologia, já dentro do código de ética do CFP: https://downway.com.br/demo/internalizapsicologia/ Hoje, quem pesquisa "psicóloga em São Paulo" no Google encontra outros profissionais. Com o site, essa pessoa chega até vocês e já fala no WhatsApp. Posso mostrar como fica no ar? | Q20: Oi! Conseguiu ver a prévia do site? Se quiser, ajusto cores, fotos ou textos para ficar com a cara do seu trabalho. A prévia fica no ar por 7 dias. | R20: Novo
A21: 20 | B21: A | C21: 9 | D21: Profissional | E21: Quiropraxia/Fisio | F21: quiropraxia | G21: SPQuiro Clínica de Quiropraxia | H21: @sp.quiro | I21: Zona Norte | L21: nao encontrado | O21: Abrir prévia | P21: Oi, pessoal da SPQuiro Clínica de Quiropraxia! Sou o [SEU NOME], da Downway. Acompanho o conteúdo de vocês de quiropraxia aqui no Instagram e montei uma prévia de site para a SPQuiro Clínica de Quiropraxia, com agendamento direto pelo WhatsApp: https://downway.com.br/demo/sp-quiro/ Hoje, quem pesquisa "quiropraxia na zona norte" no Google encontra outros profissionais. Com o site, essa pessoa chega até vocês e já fala no WhatsApp. Posso mostrar como fica no ar? | Q21: Oi! Conseguiu ver a prévia do site? Se quiser, ajusto cores, fotos ou textos para ficar com a cara do seu trabalho. A prévia fica no ar por 7 dias. | R21: Novo | U21: Endereço: R. Maria Amália Lopes de Azevedo, 250, sala 02
A22: 21 | B22: A | C22: 8 | D22: Profissional | E22: Advogado | F22: previdenciário | G22: Fernanda Diniz Advocacia Previdenciária | H22: @fernandadinizprev | I22: São Paulo | L22: nao encontrado | O22: Abrir prévia | P22: Oi, Fernanda! Sou o [SEU NOME], da Downway. Acompanho seu conteúdo de direito previdenciário aqui no Instagram e montei uma prévia de site para você, já seguindo as regras de publicidade da OAB (Provimento 205/2021): https://downway.com.br/demo/fernandadinizprev/ Hoje, quem pesquisa "advogado previdenciário em São Paulo" no Google encontra outros profissionais. Com o site, essa pessoa chega até você e já fala no WhatsApp. Posso mostrar como fica no ar? | Q22: Oi! Conseguiu ver a prévia do site? Se quiser, ajusto cores, fotos ou textos para ficar com a cara do seu trabalho. A prévia fica no ar por 7 dias. | R22: Novo
A23: 22 | B23: A | C23: 8 | D23: Negócio local | E23: Barbearia | F23: barbearia | G23: Barbearia Lacerda | H23: @barbearialacerda | I23: Mooca | J23: 3186 | L23: nao encontrado | O23: Abrir prévia | P23: Oi, pessoal da Barbearia Lacerda! Sou o [SEU NOME], da Downway. Curto muito o trabalho de vocês aqui no Instagram. Montei uma prévia de site para a Barbearia Lacerda só para vocês verem como fica: https://downway.com.br/demo/barbearialacerda/ Quem procura "barbearia Mooca" no Google cai nos concorrentes. Com o site, cai em vocês e já chama no WhatsApp. Abre no celular e me diz o que achou? | Q23: Oi! Conseguiu ver a prévia do site? Se quiser, ajusto cores, fotos ou textos para ficar com a cara de vocês. A prévia fica no ar por 7 dias. | R23: Novo
A24: 23 | B24: A | C24: 8 | D24: Negócio local | E24: Hamburgueria | F24: hamburgueria | G24: Smash Burger do Cheff | H24: @smashburguerdocheff | I24: Perus | J24: 26000 | L24: nao encontrado | O24: Abrir prévia | P24: Oi, pessoal da Smash Burger do Cheff! Sou o [SEU NOME], da Downway. Curto muito o trabalho de vocês aqui no Instagram. Montei uma prévia de site para a Smash Burger do Cheff só para vocês verem como fica: https://downway.com.br/demo/smashburguerdocheff/ Quem procura "hamburgueria Perus" no Google cai nos concorrentes. Com o site, cai em vocês e já chama no WhatsApp. Abre no celular e me diz o que achou? | Q24: Oi! Conseguiu ver a prévia do site? Se quiser, ajusto cores, fotos ou textos para ficar com a cara de vocês. A prévia fica no ar por 7 dias. | R24: Novo | U24: Perfil grande sem site = alvo forte
A25: 24 | B25: A | C25: 8 | D25: Negócio local | E25: Hamburgueria | F25: hamburgueria | G25: Smash Burger e Bar (Winner) | H25: @winnerburger | I25: Vila Mascote | J25: 7980 | L25: nao encontrado | O25: Abrir prévia | P25: Oi, pessoal da Smash Burger e Bar (Winner)! Sou o [SEU NOME], da Downway. Curto muito o trabalho de vocês aqui no Instagram. Montei uma prévia de site para a Smash Burger e Bar (Winner) só para vocês verem como fica: https://downway.com.br/demo/winnerburger/ Quem procura "hamburgueria Vila Mascote" no Google cai nos concorrentes. Com o site, cai em vocês e já chama no WhatsApp. Abre no celular e me diz o que achou? | Q25: Oi! Conseguiu ver a prévia do site? Se quiser, ajusto cores, fotos ou textos para ficar com a cara de vocês. A prévia fica no ar por 7 dias. | R25: Novo
A26: 25 | B26: A | C26: 8 | D26: Profissional | E26: Nutricionista | F26: nutrição | G26: Patricia Davidson Nutricionista | H26: @patriciadavidson.nutri | I26: São Paulo | L26: nao encontrado | O26: Abrir prévia | P26: Oi, Patricia! Sou o [SEU NOME], da Downway. Acompanho seu conteúdo de nutrição aqui no Instagram e montei uma prévia de site para você, já com o CRN em destaque e dentro das regras do conselho: https://downway.com.br/demo/patriciadavidson-nutri/ Hoje, quem pesquisa "nutricionista em São Paulo" no Google encontra outros profissionais. Com o site, essa pessoa chega até você e já fala no WhatsApp. Posso mostrar como fica no ar? | Q26: Oi! Conseguiu ver a prévia do site? Se quiser, ajusto cores, fotos ou textos para ficar com a cara do seu trabalho. A prévia fica no ar por 7 dias. | R26: Novo
A27: 26 | B27: A | C27: 8 | D27: Profissional | E27: Nutricionista | F27: nutrição | G27: Paula Paraíso Nutricionista | H27: @nutripaulaparaiso | I27: São Paulo | L27: nao encontrado | O27: Abrir prévia | P27: Oi, Paula! Sou o [SEU NOME], da Downway. Acompanho seu conteúdo de nutrição aqui no Instagram e montei uma prévia de site para você, já com o CRN em destaque e dentro das regras do conselho: https://downway.com.br/demo/nutripaulaparaiso/ Hoje, quem pesquisa "nutricionista em São Paulo" no Google encontra outros profissionais. Com o site, essa pessoa chega até você e já fala no WhatsApp. Posso mostrar como fica no ar? | Q27: Oi! Conseguiu ver a prévia do site? Se quiser, ajusto cores, fotos ou textos para ficar com a cara do seu trabalho. A prévia fica no ar por 7 dias. | R27: Novo
A28: 27 | B28: A | C28: 8 | D28: Profissional | E28: Nutricionista | F28: nutrição | G28: Thais Pereira Nutrição Esportiva | H28: @thaispereiranutri | I28: Mooca | L28: nao encontrado | O28: Abrir prévia | P28: Oi, Thais! Sou o [SEU NOME], da Downway. Acompanho seu conteúdo de nutrição aqui no Instagram e montei uma prévia de site para você, já com o CRN em destaque e dentro das regras do conselho: https://downway.com.br/demo/thaispereiranutri/ Hoje, quem pesquisa "nutricionista em São Paulo" no Google encontra outros profissionais. Com o site, essa pessoa chega até você e já fala no WhatsApp. Posso mostrar como fica no ar? | Q28: Oi! Conseguiu ver a prévia do site? Se quiser, ajusto cores, fotos ou textos para ficar com a cara do seu trabalho. A prévia fica no ar por 7 dias. | R28: Novo
A29: 28 | B29: A | C29: 8 | D29: Negócio local | E29: Pizzaria | F29: pizzaria | G29: São Paulo Pizzas | H29: @saopaulopizzas | I29: Bela Vista | J29: 1304 | L29: nao encontrado | O29: Abrir prévia | P29: Oi, pessoal da São Paulo Pizzas! Sou o [SEU NOME], da Downway. Curto muito o trabalho de vocês aqui no Instagram. Montei uma prévia de site para a São Paulo Pizzas só para vocês verem como fica: https://downway.com.br/demo/saopaulopizzas/ Quem procura "pizzaria Bela Vista" no Google cai nos concorrentes. Com o site, cai em vocês e já chama no WhatsApp. Abre no celular e me diz o que achou? | Q29: Oi! Conseguiu ver a prévia do site? Se quiser, ajusto cores, fotos ou textos para ficar com a cara de vocês. A prévia fica no ar por 7 dias. | R29: Novo
A30: 29 | B30: A | C30: 8 | D30: Profissional | E30: Psicólogo | F30: psicologia | G30: Psicologia Clínica Tatuapé | H30: @psicotatuape | I30: Tatuapé | L30: nao encontrado | O30: Abrir prévia | P30: Oi, pessoal da Psicologia Clínica Tatuapé! Sou o [SEU NOME], da Downway. Acompanho o conteúdo de vocês de psicologia aqui no Instagram e montei uma prévia de site para a Psicologia Clínica Tatuapé, já dentro do código de ética do CFP: https://downway.com.br/demo/psicotatuape/ Hoje, quem pesquisa "psicóloga em São Paulo" no Google encontra outros profissionais. Com o site, essa pessoa chega até vocês e já fala no WhatsApp. Posso mostrar como fica no ar? | Q30: Oi! Conseguiu ver a prévia do site? Se quiser, ajusto cores, fotos ou textos para ficar com a cara do seu trabalho. A prévia fica no ar por 7 dias. | R30: Novo
A31: 30 | B31: B | C31: 8 | D31: Profissional | E31: Médico | F31: dermatologia | G31: Dra. Sarah Brasil | H31: @sarahbrasildermato | I31: São Paulo | K31: RQE 5241 | L31: nao encontrado | O31: Abrir prévia | P31: Oi, Dra. Sarah! Sou o [SEU NOME], da Downway. Acompanho seu conteúdo de dermatologia aqui no Instagram e montei uma prévia de site para você, já seguindo a resolução de publicidade médica do CFM (2.336/2023): https://downway.com.br/demo/sarahbrasildermato/ Hoje, quem pesquisa "dermatologista em São Paulo" no Google encontra outros profissionais. Com o site, essa pessoa chega até você e já fala no WhatsApp. Posso mostrar como fica no ar? | Q31: Oi! Conseguiu ver a prévia do site? Se quiser, ajusto cores, fotos ou textos para ficar com a cara do seu trabalho. A prévia fica no ar por 7 dias. | R31: Novo | U31: Confirmar cidade e CRM
A32: 31 | B32: A | C32: 7 | D32: Negócio local | E32: Barbearia | F32: barbearia | G32: Barbearia Bresser | H32: @bresserbarbearia | I32: Mooca | J32: 1603 | L32: nao encontrado | O32: Abrir prévia | P32: Oi, pessoal da Barbearia Bresser! Sou o [SEU NOME], da Downway. Curto muito o trabalho de vocês aqui no Instagram. Montei uma prévia de site para a Barbearia Bresser só para vocês verem como fica: https://downway.com.br/demo/bresserbarbearia/ Quem procura "barbearia Mooca" no Google cai nos concorrentes. Com o site, cai em vocês e já chama no WhatsApp. Abre no celular e me diz o que achou? | Q32: Oi! Conseguiu ver a prévia do site? Se quiser, ajusto cores, fotos ou textos para ficar com a cara de vocês. A prévia fica no ar por 7 dias. | R32: Novo
A33: 32 | B33: A | C33: 7 | D33: Negócio local | E33: Confeitaria | F33: confeitaria | G33: Casa Caramelo | H33: @casacaramelo230 | I33: São Paulo | J33: 5539 | L33: nao encontrado | O33: Abrir prévia | P33: Oi, pessoal da Casa Caramelo! Sou o [SEU NOME], da Downway. Curto muito o trabalho de vocês aqui no Instagram. Montei uma prévia de site para a Casa Caramelo só para vocês verem como fica: https://downway.com.br/demo/casacaramelo230/ Quem procura "confeitaria São Paulo" no Google cai nos concorrentes. Com o site, cai em vocês e já chama no WhatsApp. Abre no celular e me diz o que achou? | Q33: Oi! Conseguiu ver a prévia do site? Se quiser, ajusto cores, fotos ou textos para ficar com a cara de vocês. A prévia fica no ar por 7 dias. | R33: Novo
A34: 33 | B34: A | C34: 7 | D34: Negócio local | E34: Confeitaria | F34: confeitaria | G34: Confeitaria Mais Bolo | H34: @confeitariamaisbolo | I34: São Paulo | J34: 6577 | L34: nao encontrado | O34: Abrir prévia | P34: Oi, pessoal da Confeitaria Mais Bolo! Sou o [SEU NOME], da Downway. Curto muito o trabalho de vocês aqui no Instagram. Montei uma prévia de site para a Confeitaria Mais Bolo só para vocês verem como fica: https://downway.com.br/demo/confeitariamaisbolo/ Quem procura "confeitaria São Paulo" no Google cai nos concorrentes. Com o site, cai em vocês e já chama no WhatsApp. Abre no celular e me diz o que achou? | Q34: Oi! Conseguiu ver a prévia do site? Se quiser, ajusto cores, fotos ou textos para ficar com a cara de vocês. A prévia fica no ar por 7 dias. | R34: Novo
A35: 34 | B35: A | C35: 7 | D35: Negócio local | E35: Cílios/sobrancelhas | F35: lash | G35: Lash In | H35: @studio.lashin | I35: Rua Eça de Queiroz, 267 | L35: nao encontrado | O35: Abrir prévia | P35: Oi, pessoal da Lash In! Sou o [SEU NOME], da Downway. Curto muito o trabalho de vocês aqui no Instagram. Montei uma prévia de site para a Lash In só para vocês verem como fica: https://downway.com.br/demo/studio-lashin/ Quem procura "cílios/sobrancelhas Rua Eça de Queiroz, 267" no Google cai nos concorrentes. Com o site, cai em vocês e já chama no WhatsApp. Abre no celular e me diz o que achou? | Q35: Oi! Conseguiu ver a prévia do site? Se quiser, ajusto cores, fotos ou textos para ficar com a cara de vocês. A prévia fica no ar por 7 dias. | R35: Novo | U35: Vende curso = site com página de curso
A36: 35 | B36: A | C36: 7 | D36: Negócio local | E36: Estética automotiva | F36: estética automotiva | G36: GB Estética Automotiva | H36: @gb.estetica.automotiva | I36: Vila Formosa | L36: nao encontrado | O36: Abrir prévia | P36: Oi, pessoal da GB Estética Automotiva! Sou o [SEU NOME], da Downway. Curto muito o trabalho de vocês aqui no Instagram. Montei uma prévia de site para a GB Estética Automotiva só para vocês verem como fica: https://downway.com.br/demo/gb-estetica-automotiva/ Quem procura "estética automotiva Vila Formosa" no Google cai nos concorrentes. Com o site, cai em vocês e já chama no WhatsApp. Abre no celular e me diz o que achou? | Q36: Oi! Conseguiu ver a prévia do site? Se quiser, ajusto cores, fotos ou textos para ficar com a cara de vocês. A prévia fica no ar por 7 dias. | R36: Novo
A37: 36 | B37: A | C37: 7 | D37: Negócio local | E37: Estética automotiva | F37: estética automotiva | G37: High Clean | H37: @highclean.sp | I37: Brooklin | J37: 4562 | L37: nao encontrado | O37: Abrir prévia | P37: Oi, pessoal da High Clean! Sou o [SEU NOME], da Downway. Curto muito o trabalho de vocês aqui no Instagram. Montei uma prévia de site para a High Clean só para vocês verem como fica: https://downway.com.br/demo/highclean-sp/ Quem procura "estética automotiva Brooklin" no Google cai nos concorrentes. Com o site, cai em vocês e já chama no WhatsApp. Abre no celular e me diz o que achou? | Q37: Oi! Conseguiu ver a prévia do site? Se quiser, ajusto cores, fotos ou textos para ficar com a cara de vocês. A prévia fica no ar por 7 dias. | R37: Novo | U37: Ticket alto
A38: 37 | B38: A | C38: 7 | D38: Negócio local | E38: Estética automotiva | F38: estética automotiva | G38: Lava Rápido 24 Horas | H38: @lava24horas | I38: Morumbi | L38: nao encontrado | O38: Abrir prévia | P38: Oi, pessoal da Lava Rápido 24 Horas! Sou o [SEU NOME], da Downway. Curto muito o trabalho de vocês aqui no Instagram. Montei uma prévia de site para a Lava Rápido 24 Horas só para vocês verem como fica: https://downway.com.br/demo/lava24horas/ Quem procura "estética automotiva Morumbi" no Google cai nos concorrentes. Com o site, cai em vocês e já chama no WhatsApp. Abre no celular e me diz o que achou? | Q38: Oi! Conseguiu ver a prévia do site? Se quiser, ajusto cores, fotos ou textos para ficar com a cara de vocês. A prévia fica no ar por 7 dias. | R38: Novo
A39: 38 | B39: A | C39: 7 | D39: Negócio local | E39: Hamburgueria | F39: hamburgueria | G39: Smash Brothers | H39: @smashbrothersburger | I39: confirmar | J39: 9398 | L39: nao encontrado | O39: Abrir prévia | P39: Oi, pessoal da Smash Brothers! Sou o [SEU NOME], da Downway. Curto muito o trabalho de vocês aqui no Instagram. Montei uma prévia de site para a Smash Brothers só para vocês verem como fica: https://downway.com.br/demo/smashbrothersburger/ Quem procura "hamburgueria confirmar" no Google cai nos concorrentes. Com o site, cai em vocês e já chama no WhatsApp. Abre no celular e me diz o que achou? | Q39: Oi! Conseguiu ver a prévia do site? Se quiser, ajusto cores, fotos ou textos para ficar com a cara de vocês. A prévia fica no ar por 7 dias. | R39: Novo
A40: 39 | B40: A | C40: 7 | D40: Negócio local | E40: Marcenaria | F40: marcenaria | G40: MA Planejados | H40: @_maplanejados | I40: Zona Leste | J40: 3249 | L40: nao encontrado | O40: Abrir prévia | P40: Oi, pessoal da MA Planejados! Sou o [SEU NOME], da Downway. Curto muito o trabalho de vocês aqui no Instagram. Montei uma prévia de site para a MA Planejados só para vocês verem como fica: https://downway.com.br/demo/maplanejados/ Quem procura "marcenaria Zona Leste" no Google cai nos concorrentes. Com o site, cai em vocês e já chama no WhatsApp. Abre no celular e me diz o que achou? | Q40: Oi! Conseguiu ver a prévia do site? Se quiser, ajusto cores, fotos ou textos para ficar com a cara de vocês. A prévia fica no ar por 7 dias. | R40: Novo | U40: Ticket alto, precisa de portfólio
...

Sheet Resumo
A1: Funil Downway
A3: Status | B3: Qtd
A4: Novo | B4: =COUNTIF(Leads!R:R,"Novo")
A5: Perfil conferido | B5: =COUNTIF(Leads!R:R,"Perfil conferido")
A6: Contatado | B6: =COUNTIF(Leads!R:R,"Contatado")
A7: Follow-up enviado | B7: =COUNTIF(Leads!R:R,"Follow-up enviado")
A8: Respondeu | B8: =COUNTIF(Leads!R:R,"Respondeu")
A9: Reunião | B9: =COUNTIF(Leads!R:R,"Reunião")
A10: Proposta | B10: =COUNTIF(Leads!R:R,"Proposta")
A11: Fechado | B11: =COUNTIF(Leads!R:R,"Fechado")
A12: Perdido | B12: =COUNTIF(Leads!R:R,"Perdido")
A13: Descartado | B13: =COUNTIF(Leads!R:R,"Descartado")
A14: Total | B14: =COUNTA(Leads!G2:G92)
A15: Taxa de resposta | B15: =IFERROR((B8+B9+B10+B11)/(B6+B7+B8+B9+B10+B11+B12),0)
A16: Faturamento (fechados × preço) | B16: =B11*997
A18: Categoria | B18: Leads | C18: Prioridade A | D18: Fechados
A19: Advogado | B19: =COUNTIF(Leads!E:E,"Advogado") | C19: =COUNTIFS(Leads!E:E,"Advogado",Leads!B:B,"A") | D19: =COUNTIFS(Leads!E:E,"Advogado",Leads!R:R,"Fechado")
A20: Barbearia | B20: =COUNTIF(Leads!E:E,"Barbearia") | C20: =COUNTIFS(Leads!E:E,"Barbearia",Leads!B:B,"A") | D20: =COUNTIFS(Leads!E:E,"Barbearia",Leads!R:R,"Fechado")
A21: Clínica de estética | B21: =COUNTIF(Leads!E:E,"Clínica de estética") | C21: =COUNTIFS(Leads!E:E,"Clínica de estética",Leads!B:B,"A") | D21: =COUNTIFS(Leads!E:E,"Clínica de estética",Leads!R:R,"Fechado")
A22: Confeitaria | B22: =COUNTIF(Leads!E:E,"Confeitaria") | C22: =COUNTIFS(Leads!E:E,"Confeitaria",Leads!B:B,"A") | D22: =COUNTIFS(Leads!E:E,"Confeitaria",Leads!R:R,"Fechado")
A23: Cílios/sobrancelhas | B23: =COUNTIF(Leads!E:E,"Cílios/sobrancelhas") | C23: =COUNTIFS(Leads!E:E,"Cílios/sobrancelhas",Leads!B:B,"A") | D23: =COUNTIFS(Leads!E:E,"Cílios/sobrancelhas",Leads!R:R,"Fechado")
A24: Dentista | B24: =COUNTIF(Leads!E:E,"Dentista") | C24: =COUNTIFS(Leads!E:E,"Dentista",Leads!B:B,"A") | D24: =COUNTIFS(Leads!E:E,"Dentista",Leads!R:R,"Fechado")
A25: Estética automotiva | B25: =COUNTIF(Leads!E:E,"Estética automotiva") | C25: =COUNTIFS(Leads!E:E,"Estética automotiva",Leads!B:B,"A") | D25: =COUNTIFS(Leads!E:E,"Estética automotiva",Leads!R:R,"Fechado")
A26: Hamburgueria | B26: =COUNTIF(Leads!E:E,"Hamburgueria") | C26: =COUNTIFS(Leads!E:E,"Hamburgueria",Leads!B:B,"A") | D26: =COUNTIFS(Leads!E:E,"Hamburgueria",Leads!R:R,"Fechado")
A27: Marcenaria | B27: =COUNTIF(Leads!E:E,"Marcenaria") | C27: =COUNTIFS(Leads!E:E,"Marcenaria",Leads!B:B,"A") | D27: =COUNTIFS(Leads!E:E,"Marcenaria",Leads!R:R,"Fechado")
A28: Médico | B28: =COUNTIF(Leads!E:E,"Médico") | C28: =COUNTIFS(Leads!E:E,"Médico",Leads!B:B,"A") | D28: =COUNTIFS(Leads!E:E,"Médico",Leads!R:R,"Fechado")
A29: Nutricionista | B29: =COUNTIF(Leads!E:E,"Nutricionista") | C29: =COUNTIFS(Leads!E:E,"Nutricionista",Leads!B:B,"A") | D29: =COUNTIFS(Leads!E:E,"Nutricionista",Leads!R:R,"Fechado")
A30: Pet shop | B30: =COUNTIF(Leads!E:E,"Pet shop") | C30: =COUNTIFS(Leads!E:E,"Pet shop",Leads!B:B,"A") | D30: =COUNTIFS(Leads!E:E,"Pet shop",Leads!R:R,"Fechado")
A31: Pilates/funcional | B31: =COUNTIF(Leads!E:E,"Pilates/funcional") | C31: =COUNTIFS(Leads!E:E,"Pilates/funcional",Leads!B:B,"A") | D31: =COUNTIFS(Leads!E:E,"Pilates/funcional",Leads!R:R,"Fechado")
A32: Pizzaria | B32: =COUNTIF(Leads!E:E,"Pizzaria") | C32: =COUNTIFS(Leads!E:E,"Pizzaria",Leads!B:B,"A") | D32: =COUNTIFS(Leads!E:E,"Pizzaria",Leads!R:R,"Fechado")
A33: Psicólogo | B33: =COUNTIF(Leads!E:E,"Psicólogo") | C33: =COUNTIFS(Leads!E:E,"Psicólogo",Leads!B:B,"A") | D33: =COUNTIFS(Leads!E:E,"Psicólogo",Leads!R:R,"Fechado")
A34: Quiropraxia/Fisio | B34: =COUNTIF(Leads!E:E,"Quiropraxia/Fisio") | C34: =COUNTIFS(Leads!E:E,"Quiropraxia/Fisio",Leads!B:B,"A") | D34: =COUNTIFS(Leads!E:E,"Quiropraxia/Fisio",Leads!R:R,"Fechado")
A35: Salão de beleza | B35: =COUNTIF(Leads!E:E,"Salão de beleza") | C35: =COUNTIFS(Leads!E:E,"Salão de beleza",Leads!B:B,"A") | D35: =COUNTIFS(Leads!E:E,"Salão de beleza",Leads!R:R,"Fechado")
A36: Unhas | B36: =COUNTIF(Leads!E:E,"Unhas") | C36: =COUNTIFS(Leads!E:E,"Unhas",Leads!B:B,"A") | D36: =COUNTIFS(Leads!E:E,"Unhas",Leads!R:R,"Fechado")

Sheet Como usar
A1: COMO USAR ESTA PLANILHA
A3: 1. Comece pelos leads de maior Score (já estão no topo). Score vai de 0 a 10.
A4: 2. Abra o Instagram do lead (coluna H). Confira: o link da bio NÃO é um site próprio e o último post tem menos de 15 dias. Se não passar, marque "Descartado".
A5: 3. Se passou, marque "Perfil conferido" e rode: node generator/instagram.mjs <slug> && npm run build (puxa logo e fotos reais).
A6: 4. Suba dist/demo/ para downway.com.br/demo/ e abra a prévia (coluna O) no celular para conferir.
A7: 5. Copie a Mensagem 1 (coluna P), troque [SEU NOME] e mande por DM. Marque "Contatado" e a data.
A8: 6. Dois dias sem resposta: mande o Follow-up (coluna Q) e marque "Follow-up enviado".
A9: 7. Meta: 10 abordagens por dia. Acompanhe a taxa de resposta na aba Resumo.
A11: REGRAS DE OURO
A12: • Mande as DMs à mão, uma a uma. Ferramenta de disparo em massa faz o Instagram bloquear a conta.
A13: • Advogados, médicos, psicólogos e nutricionistas: o site já sai sem preço, sem depoimento e sem promessa de resultado, com o registro visível. Isso é argumento de venda: "seu site já nasce dentro das regras do conselho".
A14: • Quem disser não ou não responder em 15 dias: apague a prévia do servidor.
... A21: "Meu conselho não deixa" → O site já segue as regras (registro visível, sem preço, sem promessa, sem depoimento). Posso te mostrar ponto por ponto.
